Workbook
Name _Toc126584005: Proyek!#REF!
Name _Toc126584005: 'Proyek PPT'!#REF!
Name _Toc126584005: #REF!
Name HariLibur2020: #REF!
Name TabelNA: #REF!
Name TargetHK: #REF!
Name Tkomoditi: #REF!

Sheet WG BI Wide 2026 (2)
A1: WG-1
A2: Surrounding BIFAST Multiyears
A3: JAN | B3: FEB | C3: MAR | D3: APR | E3: MEI | F3: JUN | G3: JUL | H3: AUG | I3: SEP | J3: OCT | K3: NOV | L3: DEC
A4: 0.08 | B4: 0.1 | C4: 0.12 | D4: 0.15 | E4: 0.175 | F4: 0.2 | G4: 0.215 | H4: 0.23 | I4: 0.245 | J4: 0.26 | K4: 0.275 | L4: 0.3
A5: Surrounding BIFAST 2026
A6: JAN | B6: FEB | C6: MAR | D6: APR | E6: MEI | F6: JUN | G6: JUL | H6: AUG | I6: SEP | J6: OCT | K6: NOV | L6: DEC
A7: =A4/$L$4 -> 0.26666667 | B7: =B4/$L$4 -> 0.33333333 | C7: =C4/$L$4 -> 0.4 | D7: =D4/$L$4 -> 0.5 | E7: =E4/$L$4 -> 0.58333333 | F7: =F4/$L$4 -> 0.66666667 | G7: =G4/$L$4 -> 0.71666667 | H7: =H4/$L$4 -> 0.76666667 | ... L7: =L4/$L$4 -> 1
A9: WG-2
A10: Surrounding BI-RTGS Gen III (Multiyears)
A11: JAN | B11: FEB | C11: MAR | D11: APR | E11: MEI | F11: JUN | G11: JUL | H11: AUG | I11: SEP | J11: OCT | K11: NOV | L11: DEC
A12: 0 | B12: 0 | C12: 0 | D12: 0 | E12: 0 | F12: 0 | G12: 0 | H12: 0 | I12: 0 | J12: 0.016 | K12: 0.03 | L12: 0.045
A13: Surrounding BI-RTGS Gen III 2026
A14: JAN | B14: FEB | C14: MAR | D14: APR | E14: MEI | F14: JUN | G14: JUL | H14: AUG | I14: SEP | J14: OCT | K14: NOV | L14: DEC
A15: =A12/$L$12 -> 0 | B15: =B12/$L$12 -> 0 | C15: =C12/$L$12 -> 0 | D15: =D12/$L$12 -> 0 | E15: =E12/$L$12 -> 0 | F15: =F12/$L$12 -> 0 | G15: =G12/$L$12 -> 0 | H15: =H12/$L$12 -> 0 | ... L15: =L12/$L$12 -> 1
A17: Transaksi Repo SVBI dan SUVBI valas (Tahap 1) 2026
A18: JAN | B18: FEB | C18: MAR | D18: APR | E18: MEI | F18: JUN | G18: JUL | H18: AUG | I18: SEP | J18: OCT | K18: NOV | L18: DEC
A19: 0.2 | B19: 0.45 | C19: 0.875 | D19: 1 | E19: 1 | F19: 1 | G19: 1 | H19: 1 | I19: 1 | J19: 1 | K19: 1 | L19: 1
A21: Transaksi Repo SVBI dan SUVBI Rupiah (CCR - Tahap 2) Multiyears
A22: JAN | B22: FEB | C22: MAR | D22: APR | E22: MEI | F22: JUN | G22: JUL | H22: AUG | I22: SEP | J22: OCT | K22: NOV | L22: DEC
A23: 0 | B23: 0 | C23: 0 | D23: 0 | E23: 0 | F23: 0 | G23: 0 | H23: 0 | I23: 0 | J23: 0.075 | K23: 0.15 | L23: 0.2
A24: Transaksi Repo SVBI dan SUVBI Rupiah (CCR - Tahap 2) 2026
A25: JAN | B25: FEB | C25: MAR | D25: APR | E25: MEI | F25: JUN | G25: JUL | H25: AUG | I25: SEP | J25: OCT | K25: NOV | L25: DEC
A26: =A23/$L$23 -> 0 | B26: =B23/$L$23 -> 0 | C26: =C23/$L$23 -> 0 | D26: =D23/$L$23 -> 0 | E26: =E23/$L$23 -> 0 | F26: =F23/$L$23 -> 0 | G26: =G23/$L$23 -> 0 | H26: =H23/$L$23 -> 0 | ... L26: =L23/$L$23 -> 1
A28: WG-2
A29: CBS Multiyears
A30: JAN | B30: FEB | C30: MAR | D30: APR | E30: MEI | F30: JUN | G30: JUL | H30: AUG | I30: SEP | J30: OCT | K30: NOV | L30: DEC
A31: 0.08 | B31: 0.1 | C31: 0.12 | D31: 0.15 | E31: 0.175 | F31: 0.2 | G31: 0.215 | H31: 0.23 | I31: 0.245 | J31: 0.26 | K31: 0.275 | L31: 0.3
A32: CBS 2026
A33: JAN | B33: FEB | C33: MAR | D33: APR | E33: MEI | F33: JUN | G33: JUL | H33: AUG | I33: SEP | J33: OCT | K33: NOV | L33: DEC
A34: =A31/$L$4 -> 0.26666667 | B34: =B31/$L$4 -> 0.33333333 | C34: =C31/$L$4 -> 0.4 | D34: =D31/$L$4 -> 0.5 | E34: =E31/$L$4 -> 0.58333333 | F34: =F31/$L$4 -> 0.66666667 | G34: =G31/$L$4 -> 0.71666667 | H34: =H31/$L$4 -> 0.76666667 | ... L34: =L31/$L$4 -> 1
K41: =35/8 -> 4.375 | L41: =K41*6 -> 26.25 | M41: =L41+26 -> 52.25
C47: Target
C48: Pengembangan Product OM Pro Market (Rupiah dan Valas) Multiyears
C49: JAN | D49: FEB | E49: MAR | F49: APR | G49: MEI | H49: JUN | I49: JUL | J49: AUG | K49: SEP | L49: OCT | M49: NOV | N49: DEC
B50: AVERAGE | C50: =AVERAGE(C52:C64) -> 0.069230769 | D50: =AVERAGE(D52:D64) -> 0.125 | E50: =AVERAGE(E52:E64) -> 0.15769231 | F50: =AVERAGE(F52:F64) -> 0.18230769 | G50: =AVERAGE(G52:G64) -> 0.23307692 | H50: =AVERAGE(H52:H64) -> 0.25384615 | I50: =AVERAGE(I52:I64) -> 0.29423077 | J50: =AVERAGE(J52:J64) -> 0.30769231 | ... N50: =AVERAGE(N52:N64) -> 0.40384615
E51: =E50/N50 -> 0.39047619 | H51: =H50/N50 -> 0.62857143 | K51: =K50/N50 -> 0.8047619 | N51: =N50/N50 -> 1
B52: Penambahan Portfolio SBN AC/HTM pada transaksi OM | C52: 0.45 | D52: 0.875 | E52: 1 | F52: 1 | G52: 1 | H52: 1 | I52: 1 | J52: 1 | K52: 1 | L52: 1 | M52: 1 | N52: 1
B53: Reopening SRBI - Tahap 2 (Searchable collateral) | C53: 0.15 | D53: 0.15 | E53: 0.15 | F53: 0.15 | G53: 0.3 | H53: 0.45 | I53: 0.8 | J53: 0.9 | K53: 0.95 | L53: 0.95 | M53: 1 | N53: 1
B54: Penerbitan Bank Indonesia Floating Rate Note (BI-FRN) | C54: 0.15 | D54: 0.3 | E54: 0.45 | F54: 0.57 | G54: 0.7 | H54: 0.8 | I54: 0.875 | J54: 0.9 | K54: 0.925 | L54: 0.95 | M54: 1 | N54: 1
B55: Integrasi dengan Market Operator untuk Transaksi OM dg Agent Bank | C55: 0 | D55: 0 | E55: 0 | F55: 0 | G55: 0 | H55: 0 | I55: 0 | J55: 0 | K55: 0 | L55: 0 | M55: 0 | N55: 0
...

Sheet WG BI Wide 2026
A1: WG-1
A2: Surrounding BIFAST Multiyears
A3: JAN | B3: FEB | C3: MAR | D3: APR | E3: MEI | F3: JUN | G3: JUL | H3: AUG | I3: SEP | J3: OCT | K3: NOV | L3: DEC
A4: 0.135 | B4: 0.14 | C4: 0.15 | D4: 0.2 | E4: 0.225 | F4: 0.25 | G4: 0.26 | H4: 0.27 | I4: 0.28 | J4: 0.29 | K4: 0.295 | L4: 0.3
A5: Surrounding BIFAST 2026
A6: JAN | B6: FEB | C6: MAR | D6: APR | E6: MEI | F6: JUN | G6: JUL | H6: AUG | I6: SEP | J6: OCT | K6: NOV | L6: DEC
A7: =A4/$L$4 -> 0.45 | B7: =B4/$L$4 -> 0.46666667 | C7: =C4/$L$4 -> 0.5 | D7: =D4/$L$4 -> 0.66666667 | E7: =E4/$L$4 -> 0.75 | F7: =F4/$L$4 -> 0.83333333 | G7: =G4/$L$4 -> 0.86666667 | H7: =H4/$L$4 -> 0.9 | ... L7: =L4/$L$4 -> 1
A10: WG-2
A11: Surrounding BI-RTGS Gen III (Multiyears)
A12: JAN | B12: FEB | C12: MAR | D12: APR | E12: MEI | F12: JUN | G12: JUL | H12: AUG | I12: SEP | J12: OCT | K12: NOV | L12: DEC
A13: 0 | B13: 0 | C13: 0 | D13: 0 | E13: 0 | F13: 0 | G13: 0 | H13: 0 | I13: 0 | J13: 0.016 | K13: 0.03 | L13: 0.045
A14: Surrounding BI-RTGS Gen III 2026
A15: JAN | B15: FEB | C15: MAR | D15: APR | E15: MEI | F15: JUN | G15: JUL | H15: AUG | I15: SEP | J15: OCT | K15: NOV | L15: DEC
A16: =A13/$L$13 -> 0 | B16: =B13/$L$13 -> 0 | C16: =C13/$L$13 -> 0 | D16: =D13/$L$13 -> 0 | E16: =E13/$L$13 -> 0 | F16: =F13/$L$13 -> 0 | G16: =G13/$L$13 -> 0 | H16: =H13/$L$13 -> 0 | ... L16: =L13/$L$13 -> 1
A18: WG-2
A19: CBS Multiyears
A20: JAN | B20: FEB | C20: MAR | D20: APR | E20: MEI | F20: JUN | G20: JUL | H20: AUG | I20: SEP | J20: OCT | K20: NOV | L20: DEC | O20: =25/30 -> 0.83333333
A21: 0.08 | B21: 0.1 | C21: 0.15 | D21: 0.2 | E21: 0.21 | F21: 0.22 | G21: 0.23 | H21: 0.24 | I21: 0.25 | J21: 0.26 | K21: 0.27 | L21: 0.28 | O21: =28/30 -> 0.93333333
A22: CBS 2026
A23: JAN | B23: FEB | C23: MAR | D23: APR | E23: MEI | F23: JUN | G23: JUL | H23: AUG | I23: SEP | J23: OCT | K23: NOV | L23: DEC
A24: =A21/$L$21 -> 0.28571429 | B24: =B21/$L$21 -> 0.35714286 | C24: =C21/$L$21 -> 0.53571429 | D24: =D21/$L$21 -> 0.71428571 | E24: =E21/$L$21 -> 0.75 | F24: =F21/$L$21 -> 0.78571429 | G24: =G21/$L$21 -> 0.82142857 | H24: =H21/$L$21 -> 0.85714286 | ... L24: =L21/$L$21 -> 1
B26: Pengembangan Product OM Pro Market (Rupiah dan Valas) Multiyears
B28: JAN | C28: FEB | D28: MAR | E28: APR | F28: MEI | G28: JUN | H28: JUL | I28: AUG | J28: SEP | K28: OCT | L28: NOV | M28: DEC
A29: Multi | B29: =AVERAGE(B32:B35) -> 0.05 | C29: =AVERAGE(C32:C35) -> 0.1375 | D29: =AVERAGE(D32:D35) -> 0.1825 | E29: =AVERAGE(E32:E35) -> 0.235 | F29: =AVERAGE(F32:F35) -> 0.3875 | G29: =AVERAGE(G32:G35) -> 0.4675 | H29: =AVERAGE(H32:H35) -> 0.4875 | I29: =AVERAGE(I32:I35) -> 0.505 | ... M29: =AVERAGE(M32:M35) -> 0.5625
A30: 2026 | B30: =B29/$M$29 -> 0.088888889 | C30: =C29/$M$29 -> 0.24444444 | D30: =D29/$M$29 -> 0.32444444 | E30: =E29/$M$29 -> 0.41777778 | F30: =F29/$M$29 -> 0.68888889 | G30: =G29/$M$29 -> 0.83111111 | H30: =H29/$M$29 -> 0.86666667 | I30: =I29/$M$29 -> 0.89777778 | ... M30: =M29/$M$29 -> 1
A31: Integrasi dengan Market Operator untuk Transaksi OM dg Agent Bank | B31: 0 | C31: 0 | D31: 0 | E31: 0 | F31: 0 | G31: 0 | H31: 0 | I31: 0 | J31: 0 | K31: 0 | L31: 0 | M31: 0.03
A32: Transaksi Repo SVBI dan SUVBI valas (Tahap 1) | B32: 0.05 | C32: 0.1 | D32: 0.15 | E32: 0.2 | F32: 0.75 | G32: 1 | H32: 1 | I32: 1 | J32: 1 | K32: 1 | L32: 1 | M32: 1
A33: Transaksi Repo SVBI dan SUVBI Rupiah (CCR - Tahap 2) | B33: 0 | C33: 0 | D33: 0 | E33: 0 | F33: 0 | G33: 0 | H33: 0 | I33: 0 | J33: 0 | K33: 0.05 | L33: 0.1 | M33: 0.15
A34: Penerbitan Bank Indonesia Floating Rate Note (BI-FRN) pengembangan Alternate ETP | B34: 0.15 | C34: 0.45 | D34: 0.58 | E34: 0.74 | F34: 0.8 | G34: 0.87 | H34: 0.95 | I34: 1 | J34: 1 | K34: 1 | L34: 1 | M34: 1
A35: Pengembangan Infrastruktur Penguatan Pasar Obligasi Korporasi dan EBA Tahap 2 | B35: 0 | C35: 0 | D35: 0 | E35: 0 | F35: 0 | G35: 0 | H35: 0 | I35: 0.02 | J35: 0.04 | K35: 0.06 | L35: 0.08 | M35: 0.1
A36: Pengembangan Infrastruktur Penguatan Pasar Obligasi Korporasi dan EBA Tahap 1 | B36: 1 | C36: 1 | D36: 1 | E36: 1 | F36: 1 | G36: 1 | H36: 1 | I36: 1 | J36: 1 | K36: 1 | L36: 1 | M36: 1
A37: Penambahan Portfolio SBN AC/HTM pada transaksi OM | B37: 1 | C37: 1 | D37: 1 | E37: 1 | F37: 1 | G37: 1 | H37: 1 | I37: 1 | J37: 1 | K37: 1 | L37: 1 | M37: 1
A38: Reopening SRBI - Tahap 2 (Searchable collateral) | B38: 1 | C38: 1 | D38: 1 | E38: 1 | F38: 1 | G38: 1 | H38: 1 | I38: 1 | J38: 1 | K38: 1 | L38: 1 | M38: 1
A39: Penerbitan Bank Indonesia Floating Rate Note (BI-FRN) | B39: 1 | C39: 1 | D39: 1 | E39: 1 | F39: 1 | G39: 1 | H39: 1 | I39: 1 | J39: 1 | K39: 1 | L39: 1 | M39: 1
A40: Perluasan investor SUKBI Non Bank | B40: 1 | C40: 1 | D40: 1 | E40: 1 | F40: 1 | G40: 1 | H40: 1 | I40: 1 | J40: 1 | K40: 1 | L40: 1 | M40: 1
A41: Transaksi DNDF Syariah melalui PDs | B41: 0 | C41: 0 | D41: 0 | E41: 0 | F41: 0 | G41: 0 | H41: 0 | I41: 0 | J41: 0 | K41: 0 | L41: 0 | M41: 0
A42: Integrasi BI-ETP dan CMS-OM | B42: 0 | C42: 0 | D42: 0 | E42: 0 | F42: 0 | G42: 0 | H42: 0 | I42: 0 | J42: 0 | K42: 0 | L42: 0 | M42: 0
A43: Securities Borrowing Lending BI | B43: 0 | C43: 0 | D43: 0 | E43: 0 | F43: 0 | G43: 0 | H43: 0 | I43: 0 | J43: 0 | K43: 0 | L43: 0 | M43: 0
B46: BI_WEB
B47: JAN | C47: FEB | D47: MAR | E47: APR | F47: MEI | G47: JUN | H47: JUL | I47: AUG | J47: SEP | K47: OCT | L47: NOV | M47: DEC
...

Sheet SIT Deliverables
B1: ON PROGRESS DEVELOPMENT | F1: GOLIVE | I1: NEED TO DISCUSS | K1: PERLU DISKUSI
I2: TAKOUT BECAUSE MHE IS
A3: No | B3: Kode Proyek | C3: Nama Proyek | D3: Nama Deliverables | E3: Proyek (Sub Proyek) | F3: Fungsi DPPT/DPU/DKEU-DSDM | G3: WO | H3: Size Proyek | I3: Target Implementasi | J3: % Penyelesaian Per Tahap | K3: PIC | L3: PLAN-SOLUSI SI | N3: PLAN-DESAIN | P3: PLAN-PENGEMBANGAN | R3: PLAN-PENGUJIAN SIT | T3: PLAN-PENGUJIAN UAT | V3: PLAN-IMPLEMENTASI | X3: Keterangan detail progres | Y3: PIC USER
A4: 1 | B4: P-54 | C4: ERPHRIS | D4: Pengeloaan Uang BI INV WMS | E4: Fungsi Penyesuaian Laporan Posisi Emas [DPPT] | F4: Fungsi DPPT | G4: WO-6 | H4: PPA | I4: 05-Des-25 | J4: 1 | K4: Trees | N4: 45915 | O4: 45926 | P4: 45929 | Q4: 24-Okt-25 | R4: 27-Okt-25 | S4: 45968 | T4: 45971 | U4: 45982 | V4: 45985 | W4: 05-Des-25 | X4: Sudah GOLIVE 03 Desember 2025 | Y4: Herry Prabowo DPU, Mutia Salsabila DPPT, Iip Latipudin DPU
A5: 2 | E5: Fungsi Penambahan Tipe Transaksi Data Emas Batanga | F5: Fungsi DPPT | H5: PPA | I5: 46094 | K5: Trees | N5: 46027 | O5: 46041 | P5: 46042 | Q5: 46055 | R5: 46056 | S5: 46066 | T5: 46071 | U5: 46085 | V5: 46086 | W5: 46094 | X5: Di Setting oleh DLDS untuk tipe setup an (Tidak masuk WO) | Y5: Herry Prabowo DPU, Mutia Salsabila DPPT, Iip Latipudin DPU
A7: 3 | E7: Fungsi Verifikasi Data Emas Batangan Bank Indonesia (Diskusi dengan DPPT saat pembahasan RPP setelah WO terbit untuk membahas memo pengadaan perangkat ke DLDS) | F7: Fungsi DPPT | G7: WO-9 | H7: PPA | I7: 46136 | K7: Trees | N7: 46027 | O7: 46041 | P7: 46042 | Q7: 46080 | R7: 46083 | S7: 46094 | T7: 46111 | U7: 46122 | V7: 46125 | W7: 46136 | X7: Melihat kondisi ketersediaan perangkat | Y7: Herry Prabowo DPU, Mutia Salsabila DPPT, Iip Latipudin DPU
A10: 4 | E10: Laporan Kapasitas Khazanah [DPU] | F10: Fungsi DPU | G10: WO-6 | H10: PPA | I10: 19-Des-25 | J10: 100`% | K10: Trees | N10: 45901 | O10: 45919 | P10: 45922 | Q10: 45968 | R10: 45971 | S10: 45982 | T10: 45985 | U10: 46009 | V10: 19-Des-25 | W10: 19-Des-25 | X10: Sudah GOLIVE 19 Des 2025 | Y10: Herry Prabowo DPU, Mutia Salsabila DPPT, Iip Latipudin DPU
A11: 5 | E11: Pengiriman Data Inventory | F11: Fungsi DPU | G11: WO-6 | H11: PPA | I11: 24-Okt-25 | J11: 1 | K11: Trees | N11: 45901 | O11: 45912 | P11: 45908 | Q11: 45930 | R11: 45931 | S11: 07-Okt-25 | T11: 13-Okt-25 | U11: Plan 1: 17-Okt-25 | V11: Plan 1: 20-Okt-25 | W11: Plan 1 : 07/11/2025 | X11: Sudah GOLIVE M1 Nov 2025 | Y11: Herry Prabowo DPU, Mutia Salsabila DPPT, Iip Latipudin DPU
E12: Kas Harian dan Kas Titipan Ke BISILK Secara Periodik [DPU] | U12: Realisasi : 31-Okt-25 | V12: Plan 2: 13-Okt-25 | W12: Realisasi :
V13: Realisasi :
A14: 6 | E14: Penonaktifan Fitur Transact | F14: Fungsi DPU | G14: Dibuat WO-8 Karena 2026 Fokus ke MHE IS | H14: PPA | I14: 46234 | K14: Trees | N14: 46055 | O14: 46112 | P14: 46113 | Q14: 46142 | R14: 46143 | S14: 46171 | T14: 46174 | U14: 46203 | V14: 46204 | W14: 46234 | Y14: Herry Prabowo DPU, Mutia Salsabila DPPT, Iip Latipudin DPU
A18: 7 | E18: Proses Penyimpanan Uang Rupiah dan/atau Barang Titipan Ke Khazanah Bank Indonesia | F18: Fungsi DPU | G18: Dibuat WO-8 Karena 2026 Fokus ke MHE IS | H18: PPA | I18: 46234 | K18: Trees | N18: 46055 | O18: 46112 | P18: 46113 | Q18: 46142 | R18: 46143 | S18: 46171 | T18: 46174 | U18: 46203 | V18: 46204 | W18: 46234 | Y18: Herry Prabowo DPU, Mutia Salsabila DPPT, Iip Latipudin DPU
A22: 8 | E22: Fungsi Laporan Pada Proses Pengelolaan Uang Rupiah Di Khazanah Bank Indonesia yang menggunakan Sistem Informasi ASRS | F22: Fungsi DPU | G22: Dibuat WO-8 Karena 2026 Fokus ke MHE IS | H22: PPA | I22: 46295 | K22: Trees | N22: 46113 | O22: 46142 | P22: 46132 | Q22: 46203 | R22: 46204 | S22: 46234 | T22: 46237 | U22: 46265 | V22: 46266 | W22: 46295 | Y22: Herry Prabowo DPU, Mutia Salsabila DPPT, Iip Latipudin DPU
A26: 9 | E26: Proses Pengambilan atau Penyimpanan Uang dan/atau Barang Titipan Dalam Rangka Stok Opname | F26: Fungsi DPU | G26: Dibuat WO-8 Karena 2026 Fokus ke MHE IS | H26: PPA | I26: 46295 | K26: Trees | N26: 46113 | O26: 46142 | P26: 46132 | Q26: 46203 | R26: 46204 | S26: 46234 | T26: 46237 | U26: 46265 | V26: 46266 | W26: 46295 | Y26: Herry Prabowo DPU, Mutia Salsabila DPPT, Iip Latipudin DPU
A31: 1 | B31: P-54 | C31: ERPHRIS | D31: Pengelolaan Keuangan BI (Prioritas 1 Tahap 1) | E31: Skema Import Pelaporan XML (FUNC.01.001) | F31: Fungsi DKEU (Fungsi DSDM) | G31: WO-6 | H31: PPA | I31: 45989 | J31: 1 | K31: Trees | N31: 45901 | O31: 45912 | P31: 45915 | Q31: 45954 | R31: 45957 | S31: 45968 | T31: 45971 | U31: 45982 | V31: 45985 | W31: 45989 | X31: Sudah GOLIVE 27 Nov 2025 | Y31: Diona DKEU
E32: Penyesuaian Laporan anlias Akun dan Penyesuaian WEB ADI (FUNC.01.003) | F32: Fungsi DKEU | G32: WO-6 | H32: PPA | I32: 46003 | J32: 1 | K32: Trees | N32: 45915 | O32: 45926 | P32: 45929 | Q32: 45968 | R32: 45971 | S32: 45982 | T32: 45985 | U32: 45996 | V32: 45999 | W32: 46003 | X32: Sudah GOLIVE 10 Des 2025 | Y32: Diona DKEU
E33: Laporan Monitoring Rekening Antara – Laporan Pemantauan Detail Transaksi Utang kepada Pegawai/Non Pegawai 441202 (FUNC.01.004) | F33: Fungsi DKEU | G33: WO-6 | H33: PPA | I33: 46003 | J33: 1 | K33: Trees | N33: 45908 | O33: 45919 | P33: 45922 | Q33: 45968 | R33: 45971 | S33: 45982 | T33: 45985 | U33: 45996 | V33: 45999 | W33: 46003 | X33: Sudah GOLIVE 10 Des 2025 | Y33: Diona DKEU
E34: Laporan Natura (FUNC.01.005) | F34: Fungsi DKEU | G34: WO-6 | H34: PPA | I34: 45996 | J34: 1 | K34: Trees | N34: 45929 | O34: 45940 | P34: 45943 | Q34: 45989 | R34: 45992 | S34: 46001 | T34: 46002 | U34: 46010 | V34: 46013 | W34: 46022 | X34: Sudah GOLIVE 30 Des 2025 | Y34: Diona DKEU
E35: Validasi Reclass Modul FA (FUNC.01.006) | F35: Fungsi DKEU (Fungsi DPRN) | G35: WO-6 | H35: PPA | I35: 45989 | J35: 1 | K35: Trees | N35: 45915 | O35: 45926 | P35: 45929 | Q35: 45954 | R35: 45957 | S35: 45968 | T35: 45971 | U35: 45982 | V35: 45985 | W35: 45989 | X35: Sudah GOLIVE 26 Nov 2025 | Y35: Diona DKEU
A36: 2 | B36: P-54 | C36: ERPHRIS | D36: Laporan Remunerasi BI (Prioritas 1) | E36: Pemenuhan Internal | F36: Fungsi DSDM | G36: WO-6 | H36: PPA | I36: 05 Des 25 | J36: 1 | K36: Trees | N36: 45901 | O36: 45905 | P36: 45908 | Q36: 45961 | R36: 45964 | S36: 45975 | T36: 45978 | U36: 45989 | V36: 01 Des 25 | W36: 05 Des 25 | X36: Sudah GOLIVE 01 Des 2025 | Y36: Jihan DSDM
E37: (FUNC.PI.001, FUNC.PI.002, FUNC.PI.005, FUNC.PI.006, FUNC.PI.007, FUNC.PI.008, dan FUNC.PI.009)
E38: Penyesuaian Pembayaran Travel dan Gaji Melalui BI-FAST dan RTGS (FUNC.FAST.001) | F38: Fungsi DSDM | G38: WO-6 | H38: PPA | I38: 45954 | J38: 1 | K38: Trees | N38: 45901 | O38: 45905 | P38: 45908 | Q38: 45936 | R38: 45938 | S38: 45944 | T38: 45944 | U38: 45947 | V38: 45950 | W38: 45954 | X38: Sudah GOLIVE 24 Okt 2025 | Y38: Jihan DSDM
E39: Penyesuaian Perhitungan Pajak Penghasilan (PPh 21) Pegawai dan BSBI (FUNC.TAX.001, FUNC.TAX.002, FUNC.TAX.004) | F39: Fungsi DSDM | G39: WO-6 | H39: PPA | I39: 45996 | J39: 1 | K39: Trees | N39: 45901 | O39: 45905 | P39: 45908 | Q39: 45961 | R39: 45964 | S39: 45975 | T39: 45978 | U39: 45989 | V39: 45992 | W39: 45996 | X39: Sudah GOLIVE 05 Des 2025 | Y39: Jihan DSDM
A40: 3 | B40: P-61 | C40: LMS-BI | D40: Integrasi LMS | E40: Integrasi LMS dengan ERPHRIS | F40: Fungsi DSDM | G40: WO-6 | H40: PPA | I40: 45996 | J40: 1 | K40: Trees | N40: 45901 | O40: 45912 | P40: 45908 | Q40: Plan 1: 31/10/2025 | R40: Plan 1 : 03/11/2025 | S40: Plan 1 :14/11/2025 | T40: Plan 1: 17/11/2025 | U40: 45989 | V40: 45992 | W40: 45996 | X40: Sudah GOLIVE 11 Des 2025 | Y40: Jihan DSDM
Q41: Realisasi : 11/11/2025 | R41: Plan 2[Proposed by Hafizh] : 11/11/2025 | S41: Plan 2 [Proposed by Hafizh] : 21/11/2025 | T41: Plan 2 [Proposed by Hafizh] : 21/11/2025
A43: 1 | B43: P-54 | C43: ERPHRIS | D43: Pengelolaan Keuangan BI (Prioritas 1 Tahap 2) | E43: Pertanggungjawaban Uang Muka | F43: Fungsi DKEU | G43: WO-9 | H43: PPA | I43: 46129 | K43: Trees | N43: 45931 | O43: 45989 | P43: 45992 | Q43: 46073 | R43: 46076 | S43: 46087 | T43: 46090 | U43: 46114 | V43: 46118 | W43: 46129 | X43: Subject to discuss ke DKEU terkait | Y43: Diona DKEU
X44: fitur Cancellation VA sebelum
X45: Desain Selesai ;
X46: 1. Pembahasan internal dulu dengan CBS (Dalam minggu ini sebelum M4 Nov 2025)
X47: 2. Pembahasan dengan DKEU (Dalam minggu ini, sebelum M4 Nov 2025)
E49: Penyesuaian Laporan Detail Kesesuaian Natural Akun Penyusutan | F49: Fungsi DKEU | G49: WO-9 | H49: PPA | I49: 46129 | K49: Trees | N49: 46027 | O49: 46037 | P49: 46041 | Q49: 46073 | R49: 46076 | S49: 46087 | T49: 46090 | U49: 46114 | V49: 46118 | W49: 46129 | Y49: Diona DKEU
E50: Laporan Rekapitulasi Bulanan Aktiva Tetap yang Belum Dilakukan Penyusutan | F50: Fungsi DKEU | G50: WO-9 | H50: PPA | I50: 46122 | K50: Trees | N50: 46006 | O50: 46031 | P50: 46034 | Q50: 46066 | R50: 46069 | S50: 46080 | T50: 46083 | U50: 46108 | V50: 46111 | W50: 46122 | Y50: Diona DKEU
E51: Laporan monitoring Status Receipt | F51: Fungsi DKEU | G51: WO-9 | H51: PPA | I51: 46129 | K51: Trees | N51: 46027 | O51: 46037 | P51: 46041 | Q51: 46073 | R51: 46076 | S51: 46087 | T51: 46090 | U51: 46114 | V51: 46118 | W51: 46129 | Y51: Diona DKEU
E52: Laporan monitoring Account Receivable | F52: Fungsi DKEU | G52: WO-9 | H52: PPA | I52: 46122 | K52: Trees | N52: 46006 | O52: 46031 | P52: 46034 | Q52: 46066 | R52: 46069 | S52: 46080 | T52: 46083 | U52: 46108 | V52: 46111 | W52: 46122 | Y52: Diona DKEU
A53: 2 | B53: P-54 | C53: ERPHRIS | D53: Pengelolaan Keuangan BI (Prioritas 2) | E53: Pop Up Message untuk BI-FAST saat Pendaftaran Vendor | F53: Fungsi DKEU | G53: TBC | H53: PPA | I53: 46241 | K53: Trees | N53: 46125 | O53: 46136 | P53: 46139 | Q53: 46206 | R53: 46209 | S53: 46220 | T53: 46223 | U53: 46234 | V53: 46237 | W53: 46241 | Y53: Diona DKEU
E54: Upload PPN atas transaksi RTGS, BI-SSSS, BI-ETP, SKNBI dan BI-FAST | F54: Fungsi DKEU | G54: TBC | H54: PPA | I54: 46290 | K54: Trees | N54: 46153 | O54: 46171 | P54: 46175 | Q54: 46248 | R54: 46252 | S54: 46262 | T54: 46265 | U54: 46283 | V54: 46286 | W54: 46290 | Y54: Diona DKEU
E55: Laporan Pemantauan Pembukuan Jurnal Manual/Web ADI | F55: Fungsi DKEU | G55: TBC | H55: PPA | I55: 46241 | K55: Trees | N55: 46125 | O55: 46136 | P55: 46139 | Q55: 46206 | R55: 46209 | S55: 46220 | T55: 46223 | U55: 46234 | V55: 46237 | W55: 46241 | Y55: Diona DKEU
E56: Enhancement Jurnal Recurring | F56: Fungsi DKEU | G56: TBC | H56: PPA | I56: 46255 | K56: Trees | N56: 46139 | O56: 46150 | P56: 46153 | Q56: 46220 | R56: 46223 | S56: 46234 | T56: 46237 | U56: 46248 | V56: 46252 | W56: 46255 | Y56: Diona DKEU
E57: Enhancement Penyelesaian Transaksi Keuangan Terkait Validasi Debit Memo | F57: Fungsi DKEU | G57: TBC | H57: PPA | I57: 46290 | K57: Trees | N57: 46153 | O57: 46171 | P57: 46175 | Q57: 46248 | R57: 46252 | S57: 46262 | T57: 46265 | U57: 46283 | V57: 46286 | W57: 46290 | Y57: Diona DKEU
E58: Laporan Monitoring Detail Cadangan Tujuan dan Laporan Tidak Membuku | F58: Fungsi DKEU | G58: TBC | H58: PPA | I58: 46290 | K58: Trees | N58: 46153 | O58: 46171 | P58: 46175 | Q58: 46248 | R58: 46252 | S58: 46262 | T58: 46265 | U58: 46283 | V58: 46286 | W58: 46290 | Y58: Diona DKEU
...

Sheet Sheet2
A1: Start Proyek | B1: (Multiple Items)
A2: End Proyek | B2: (Multiple Items)
A4: Row Labels | B4: Count of Deliverables (Sub Proyek)
A5: Market | B5: 16
A6: Market, SP | B6: 1
A7: Market, SSK | B7: 1
A8: MD | B8: 2
A9: MI | B9: 28
A10: MI, SP | B10: 1
A11: Moneter | B11: 14
A12: Moneter, Market | B12: 3
A13: Moneter, SSK | B13: 1
A14: SP | B14: 8
A15: SSK | B15: 11
A16: Grand Total | B16: 86

Sheet Proyek
A1: dashboard | B1: PT | C1: Pilar RIVIBI | D1: Kategori | E1: No | F1: No. Sub | G1: Nama Proyek | H1: Nama Proyek Baru | I1: Deliverables (Sub Proyek) | J1: Start Proyek | K1: End Proyek | L1: Stratifikasi Aset | M1: Leveling Aset TD | N1: DMP RBT | O1: PIC Satker | P1: Portofolio | Q1: Stream | R1: Aplikasi | S1: Tahapan | T1: Progress | U1: PM | V1: % Penyelesaian | W1: Target RBT | X1: Target Implementasi | Y1: KAK | Z1: Revisit | AA1: RBT | AC1: RPP | AE1: KAK/WO | AG1: PENGADAAN-DMAP | AI1: DESAIN | AK1: PENGEMBANGAN | AM1: PENGUJIAN-SIT | AO1: PENGUJIAN-UAT | AQ1: IMPLEMENTASI | AS1: Deskripsi target | BE1: Persen Target (JANGAN DI ISI) | BQ1: Deskripsi Realisasi | CC1: Persen Realisasi | CO1: Capaian | DA1: Status Proyek | DM1: Progres terhadap 2026 | DY1: % PROGRESS MILESTONE | EH1: Keterangan detail progres | EI1: Tanggal Real Implementasi | EJ1: Target Implementasi | EK1: Tanggal RBT | EL1: Tanggal Kick Off | EM1: Tanggal Project Closure | EN1: Lesson Learned | EO1: Penjelasan dan Isu | FA1: Rencana Tindak Lanjut | FM1: PIC KMBD | FN1: PIC PM | FO1: PIC KMPPD | FP1: PIC KPPA | FQ1: PIC PKLD | FR1: Metode Pengembangan | FS1: Vendor | FT1: Ket THOS | FU1: Total
A2: Column1 | B2: Column2 | C2: Column3 | D2: Column4 | E2: Column5 | F2: Column6 | G2: Column7 | I2: Column8 | J2: Column9 | K2: Column10 | L2: Column11 | M2: Column12 | N2: Column13 | O2: Column14 | P2: Column15 | Q2: Column16 | R2: Column17 | S2: Column18 | T2: Column19 | V2: Column20 | W2: Column21 | X2: Column22 | Y2: Column23 | AA2: Start | AB2: End | AC2: Start | AD2: End | AE2: Start | AF2: End | AG2: Start | AH2: End | AI2: Start | AJ2: End | AK2: Start | AL2: End | AM2: Start | AN2: End | AO2: Start | AP2: End | AQ2: Start | AR2: End | AS2: JAN | AT2: FEB | AU2: MAR | AV2: APR | AW2: MEI | AX2: JUN | AY2: JUL | AZ2: AUG | BA2: SEP | BB2: OCT | BC2: NOV | BD2: DEC | BE2: JAN | BF2: FEB | BG2: MAR | BH2: APR | BI2: MEI | BJ2: JUN | BK2: JUL | BL2: AUG | BM2: SEP | BN2: OCT | BO2: NOV | BP2: DEC | BQ2: JAN | BR2: FEB | BS2: MAR | BT2: APR | BU2: MEI | BV2: JUN | BW2: JUL | BX2: AUG | BY2: SEP | BZ2: OCT | CA2: NOV | CB2: DEC | CC2: JAN | CD2: FEB | CE2: MAR | CF2: APR | CG2: MEI | CH2: JUN | CI2: JUL | CJ2: AUG | CK2: SEP | CL2: OCT | CM2: NOV | CN2: DEC | CO2: JAN | CP2: FEB | CQ2: MAR | CR2: APR | CS2: MEI | CT2: JUN | CU2: JUL | CV2: AUG | CW2: SEP | CX2: OCT | CY2: NOV | CZ2: DEC | DA2: JAN | DB2: FEB | DC2: MAR | DD2: APR | DE2: MEI | DF2: JUN | DG2: JUL | DH2: AUG | DI2: SEP | DJ2: OCT | DK2: NOV | DL2: DEC | DM2: JAN | DN2: FEB | DO2: MAR | DP2: APR | DQ2: MEI | DR2: JUN | DS2: JUL | DT2: AUG | DU2: SEP | DV2: OCT | DW2: NOV | DX2: DEC | DY2: RBT | DZ2: RPP | EA2: KAK/WO | EB2: PENGADAAN | EC2: DESAIN | ED2: PENGEMBANGAN | EE2: SIT | EF2: UAT | EG2: IMP | EH2: 1 | EI2: Column139 | EJ2: Column140 | EL2: Column141 | EM2: Column142 | EN2: Column143 | EO2: Jan | EP2: Feb | EQ2: Mar | ER2: Apr | ES2: Mei | ET2: Jun | EU2: Jul | EV2: Ags | EW2: Sep | EX2: Okt | EY2: Nov | EZ2: Des | FA2: Jan | FB2: Feb | FC2: Mar | FD2: Apr | FE2: Mei | FF2: Jun | FG2: Jul | FH2: Ags | FI2: Sep | FJ2: Okt | FK2: Nov | FL2: Des | FM2: Column193 | FN2: Column194 | FO2: Column194 | FP2: Column195 | FR2: Column196 | FS2: Column197 | FT2: Column198 | FU2: Column198
B3: PT03 | C3: IDPS | E3: P-1 | F3: 3 | G3: BI-FAST | H3: New BI-FAST | I3: Enhancement Aplikasi Legacy New BI-FAST | J3: 2025 | K3: 2028 | L3: S | M3: K3 | N3: Pemimpin Satker | O3: DKeu, DKSP, DPSP, DLDS | P3: WG-1 | Q3: SP, MI | R3: ERPHRIS, SOA | S3: =BQ3 -> Proses RBT-RBB | T3: =IF(V3=0%,"Not Started",IF(V3<100%,"On Progress",IF(V3=100%,"DONE"))) -> On Progress | U3: =FN3 -> Aldo Fernanda | V3: =CC3 -> 0.015 | W3: TW II 2026 | X3: =AR3 -> 47026 | Z3: New | AA3: 45962 | AB3: 46142 | AC3: 46143 | AD3: 46203 | AE3: 46174 | AF3: 46203 | AG3: 46204 | AH3: 46387 | AI3: 46388 | AJ3: 46446 | AK3: 46447 | AL3: 46811 | AM3: 46813 | AN3: 46904 | AO3: 46905 | AP3: 46996 | AQ3: 46997 | AR3: 47026 | AS3: =IF(BE3=0%,"Not Started",IF(BE3<5%,"Proses RBT-RBB",IF(BE3=5%,"Selesai RBT-RBB",IF(BE3<10%,"Proses RBT-RBL",IF(BE3=10%,"Selesai RBT-RBL",IF(BE3<15%,"Proses RBT-RBTD",IF(BE3=15%,"Selesai RBT-RBTD",IF(BE3<20%,"Proses RPP",IF(BE3=20%,"Selesai RPP",IF(BE3<25%,"Proses KAK",IF(BE3=25%,"Selesai KAK",IF(BE3<30%,"Proses Pengadaan",IF(BE3=30%,"Selesai Pengadaan",IF(BE3<45%,"Proses Desain",IF(BE3=45%,"Selesai Desain",IF(BE3<80%,"Proses Pengembangan",IF(BE3=80%,"Selesai Pengembangan",IF(BE3<87.5%,"Proses SIT",IF(BE3=87.5%,"Selesai SIT",IF(BE3<95%,"Proses UAT",IF(BE3=95%,"Selesai UAT",IF(BE3<100%,"Proses Implementasi","Selesai Implementasi")))))))))))))))))))))) -> Proses RBT-RBL | AT3: =IF(BF3=0%,"Not Started",IF(BF3<5%,"Proses RBT-RBB",IF(BF3=5%,"Selesai RBT-RBB",IF(BF3<10%,"Proses RBT-RBL",IF(BF3=10%,"Selesai RBT-RBL",IF(BF3<15%,"Proses RBT-RBTD",IF(BF3=15%,"Selesai RBT-RBTD",IF(BF3<20%,"Proses RPP",IF(BF3=20%,"Selesai RPP",IF(BF3<25%,"Proses KAK",IF(BF3=25%,"Selesai KAK",IF(BF3<30%,"Proses Pengadaan",IF(BF3=30%,"Selesai Pengadaan",IF(BF3<45%,"Proses Desain",IF(BF3=45%,"Selesai Desain",IF(BF3<80%,"Proses Pengembangan",IF(BF3=80%,"Selesai Pengembangan",IF(BF3<87.5%,"Proses SIT",IF(BF3=87.5%,"Selesai SIT",IF(BF3<95%,"Proses UAT",IF(BF3=95%,"Selesai UAT",IF(BF3<100%,"Proses Implementasi","Selesai Implementasi")))))))))))))))))))))) -> Proses RBT-RBL | AU3: =IF(BG3=0%,"Not Started",IF(BG3<5%,"Proses RBT-RBB",IF(BG3=5%,"Selesai RBT-RBB",IF(BG3<10%,"Proses RBT-RBL",IF(BG3=10%,"Selesai RBT-RBL",IF(BG3<15%,"Proses RBT-RBTD",IF(BG3=15%,"Selesai RBT-RBTD",IF(BG3<20%,"Proses RPP",IF(BG3=20%,"Selesai RPP",IF(BG3<25%,"Proses KAK",IF(BG3=25%,"Selesai KAK",IF(BG3<30%,"Proses Pengadaan",IF(BG3=30%,"Selesai Pengadaan",IF(BG3<45%,"Proses Desain",IF(BG3=45%,"Selesai Desain",IF(BG3<80%,"Proses Pengembangan",IF(BG3=80%,"Selesai Pengembangan",IF(BG3<87.5%,"Proses SIT",IF(BG3=87.5%,"Selesai SIT",IF(BG3<95%,"Proses UAT",IF(BG3=95%,"Selesai UAT",IF(BG3<100%,"Proses Implementasi","Selesai Implementasi")))))))))))))))))))))) -> Proses RBT-RBTD | AV3: =IF(BH3=0%,"Not Started",IF(BH3<5%,"Proses RBT-RBB",IF(BH3=5%,"Selesai RBT-RBB",IF(BH3<10%,"Proses RBT-RBL",IF(BH3=10%,"Selesai RBT-RBL",IF(BH3<15%,"Proses RBT-RBTD",IF(BH3=15%,"Selesai RBT-RBTD",IF(BH3<20%,"Proses RPP",IF(BH3=20%,"Selesai RPP",IF(BH3<25%,"Proses KAK",IF(BH3=25%,"Selesai KAK",IF(BH3<30%,"Proses Pengadaan",IF(BH3=30%,"Selesai Pengadaan",IF(BH3<45%,"Proses Desain",IF(BH3=45%,"Selesai Desain",IF(BH3<80%,"Proses Pengembangan",IF(BH3=80%,"Selesai Pengembangan",IF(BH3<87.5%,"Proses SIT",IF(BH3=87.5%,"Selesai SIT",IF(BH3<95%,"Proses UAT",IF(BH3=95%,"Selesai UAT",IF(BH3<100%,"Proses Implementasi","Selesai Implementasi")))))))))))))))))))))) -> Selesai RBT-RBTD | AW3: =IF(BI3=0%,"Not Started",IF(BI3<5%,"Proses RBT-RBB",IF(BI3=5%,"Selesai RBT-RBB",IF(BI3<10%,"Proses RBT-RBL",IF(BI3=10%,"Selesai RBT-RBL",IF(BI3<15%,"Proses RBT-RBTD",IF(BI3=15%,"Selesai RBT-RBTD",IF(BI3<20%,"Proses RPP",IF(BI3=20%,"Selesai RPP",IF(BI3<25%,"Proses KAK",IF(BI3=25%,"Selesai KAK",IF(BI3<30%,"Proses Pengadaan",IF(BI3=30%,"Selesai Pengadaan",IF(BI3<45%,"Proses Desain",IF(BI3=45%,"Selesai Desain",IF(BI3<80%,"Proses Pengembangan",IF(BI3=80%,"Selesai Pengembangan",IF(BI3<87.5%,"Proses SIT",IF(BI3=87.5%,"Selesai SIT",IF(BI3<95%,"Proses UAT",IF(BI3=95%,"Selesai UAT",IF(BI3<100%,"Proses Implementasi","Selesai Implementasi")))))))))))))))))))))) -> Proses RPP | AX3: =IF(BJ3=0%,"Not Started",IF(BJ3<5%,"Proses RBT-RBB",IF(BJ3=5%,"Selesai RBT-RBB",IF(BJ3<10%,"Proses RBT-RBL",IF(BJ3=10%,"Selesai RBT-RBL",IF(BJ3<15%,"Proses RBT-RBTD",IF(BJ3=15%,"Selesai RBT-RBTD",IF(BJ3<20%,"Proses RPP",IF(BJ3=20%,"Selesai RPP",IF(BJ3<25%,"Proses KAK",IF(BJ3=25%,"Selesai KAK",IF(BJ3<30%,"Proses Pengadaan",IF(BJ3=30%,"Selesai Pengadaan",IF(BJ3<45%,"Proses Desain",IF(BJ3=45%,"Selesai Desain",IF(BJ3<80%,"Proses Pengembangan",IF(BJ3=80%,"Selesai Pengembangan",IF(BJ3<87.5%,"Proses SIT",IF(BJ3=87.5%,"Selesai SIT",IF(BJ3<95%,"Proses UAT",IF(BJ3=95%,"Selesai UAT",IF(BJ3<100%,"Proses Implementasi","Selesai Implementasi")))))))))))))))))))))) -> Selesai RPP | AY3: =IF(BK3=0%,"Not Started",IF(BK3<5%,"Proses RBT-RBB",IF(BK3=5%,"Selesai RBT-RBB",IF(BK3<10%,"Proses RBT-RBL",IF(BK3=10%,"Selesai RBT-RBL",IF(BK3<15%,"Proses RBT-RBTD",IF(BK3=15%,"Selesai RBT-RBTD",IF(BK3<20%,"Proses RPP",IF(BK3=20%,"Selesai RPP",IF(BK3<25%,"Proses KAK",IF(BK3=25%,"Selesai KAK",IF(BK3<30%,"Proses Pengadaan",IF(BK3=30%,"Selesai Pengadaan",IF(BK3<45%,"Proses Desain",IF(BK3=45%,"Selesai Desain",IF(BK3<80%,"Proses Pengembangan",IF(BK3=80%,"Selesai Pengembangan",IF(BK3<87.5%,"Proses SIT",IF(BK3=87.5%,"Selesai SIT",IF(BK3<95%,"Proses UAT",IF(BK3=95%,"Selesai UAT",IF(BK3<100%,"Proses Implementasi","Selesai Implementasi")))))))))))))))))))))) -> Selesai KAK | AZ3: =IF(BL3=0%,"Not Started",IF(BL3<5%,"Proses RBT-RBB",IF(BL3=5%,"Selesai RBT-RBB",IF(BL3<10%,"Proses RBT-RBL",IF(BL3=10%,"Selesai RBT-RBL",IF(BL3<15%,"Proses RBT-RBTD",IF(BL3=15%,"Selesai RBT-RBTD",IF(BL3<20%,"Proses RPP",IF(BL3=20%,"Selesai RPP",IF(BL3<25%,"Proses KAK",IF(BL3=25%,"Selesai KAK",IF(BL3<30%,"Proses Pengadaan",IF(BL3=30%,"Selesai Pengadaan",IF(BL3<45%,"Proses Desain",IF(BL3=45%,"Selesai Desain",IF(BL3<80%,"Proses Pengembangan",IF(BL3=80%,"Selesai Pengembangan",IF(BL3<87.5%,"Proses SIT",IF(BL3=87.5%,"Selesai SIT",IF(BL3<95%,"Proses UAT",IF(BL3=95%,"Selesai UAT",IF(BL3<100%,"Proses Implementasi","Selesai Implementasi")))))))))))))))))))))) -> Proses Pengadaan | ... BD3: =IF(BP3=0%,"Not Started",IF(BP3<5%,"Proses RBT-RBB",IF(BP3=5%,"Selesai RBT-RBB",IF(BP3<10%,"Proses RBT-RBL",IF(BP3=10%,"Selesai RBT-RBL",IF(BP3<15%,"Proses RBT-RBTD",IF(BP3=15%,"Selesai RBT-RBTD",IF(BP3<20%,"Proses RPP",IF(BP3=20%,"Selesai RPP",IF(BP3<25%,"Proses KAK",IF(BP3=25%,"Selesai KAK",IF(BP3<30%,"Proses Pengadaan",IF(BP3=30%,"Selesai Pengadaan",IF(BP3<45%,"Proses Desain",IF(BP3=45%,"Selesai Desain",IF(BP3<80%,"Proses Pengembangan",IF(BP3=80%,"Selesai Pengembangan",IF(BP3<87.5%,"Proses SIT",IF(BP3=87.5%,"Selesai SIT",IF(BP3<95%,"Proses UAT",IF(BP3=95%,"Selesai UAT",IF(BP3<100%,"Proses Implementasi","Selesai Implementasi")))))))))))))))))))))) -> Selesai Pengadaan | BE3: 0.06 | BF3: 0.09 | BG3: 0.12 | BH3: 0.15 | BI3: 0.175 | BJ3: 0.2 | BK3: 0.25 | BL3: 0.26 | BM3: 0.27 | BN3: 0.28 | BO3: 0.29 | BP3: 0.3 | BQ3: =IF(CC3=0%,"Not Started",IF(CC3<5%,"Proses RBT-RBB",IF(CC3=5%,"Selesai RBT-RBB",IF(CC3<10%,"Proses RBT-RBL",IF(CC3=10%,"Selesai RBT-RBL",IF(CC3<15%,"Proses RBT-RBTD",IF(CC3=15%,"Selesai RBT-RBTD",IF(CC3<20%,"Proses RPP",IF(CC3=20%,"Selesai RPP",IF(CC3<25%,"Proses KAK",IF(CC3=25%,"Selesai KAK",IF(CC3<30%,"Proses Pengadaan",IF(CC3=30%,"Selesai Pengadaan",IF(CC3<45%,"Proses Desain",IF(CC3=45%,"Selesai Desain",IF(CC3<80%,"Proses Pengembangan",IF(CC3=80%,"Selesai Pengembangan",IF(CC3<87.5%,"Proses SIT",IF(CC3=87.5%,"Selesai SIT",IF(CC3<95%,"Proses UAT",IF(CC3=95%,"Selesai UAT",IF(CC3<100%,"Proses Implementasi","Selesai Implementasi")))))))))))))))))))))) -> Proses RBT-RBB | BR3: =IF(CD3=0%,"Not Started",IF(CD3<5%,"Proses RBT-RBB",IF(CD3=5%,"Selesai RBT-RBB",IF(CD3<10%,"Proses RBT-RBL",IF(CD3=10%,"Selesai RBT-RBL",IF(CD3<15%,"Proses RBT-RBTD",IF(CD3=15%,"Selesai RBT-RBTD",IF(CD3<20%,"Proses RPP",IF(CD3=20%,"Selesai RPP",IF(CD3<25%,"Proses KAK",IF(CD3=25%,"Selesai KAK",IF(CD3<30%,"Proses Pengadaan",IF(CD3=30%,"Selesai Pengadaan",IF(CD3<45%,"Proses Desain",IF(CD3=45%,"Selesai Desain",IF(CD3<80%,"Proses Pengembangan",IF(CD3=80%,"Selesai Pengembangan",IF(CD3<87.5%,"Proses SIT",IF(CD3=87.5%,"Selesai SIT",IF(CD3<95%,"Proses UAT",IF(CD3=95%,"Selesai UAT",IF(CD3<100%,"Proses Implementasi","Selesai Implementasi")))))))))))))))))))))) -> Not Started | BS3: =IF(CE3=0%,"Not Started",IF(CE3<5%,"Proses RBT-RBB",IF(CE3=5%,"Selesai RBT-RBB",IF(CE3<10%,"Proses RBT-RBL",IF(CE3=10%,"Selesai RBT-RBL",IF(CE3<15%,"Proses RBT-RBTD",IF(CE3=15%,"Selesai RBT-RBTD",IF(CE3<20%,"Proses RPP",IF(CE3=20%,"Selesai RPP",IF(CE3<25%,"Proses KAK",IF(CE3=25%,"Selesai KAK",IF(CE3<30%,"Proses Pengadaan",IF(CE3=30%,"Selesai Pengadaan",IF(CE3<45%,"Proses Desain",IF(CE3=45%,"Selesai Desain",IF(CE3<80%,"Proses Pengembangan",IF(CE3=80%,"Selesai Pengembangan",IF(CE3<87.5%,"Proses SIT",IF(CE3=87.5%,"Selesai SIT",IF(CE3<95%,"Proses UAT",IF(CE3=95%,"Selesai UAT",IF(CE3<100%,"Proses Implementasi","Selesai Implementasi")))))))))))))))))))))) -> Not Started | BT3: =IF(CF3=0%,"Not Started",IF(CF3<5%,"Proses RBT-RBB",IF(CF3=5%,"Selesai RBT-RBB",IF(CF3<10%,"Proses RBT-RBL",IF(CF3=10%,"Selesai RBT-RBL",IF(CF3<15%,"Proses RBT-RBTD",IF(CF3=15%,"Selesai RBT-RBTD",IF(CF3<20%,"Proses RPP",IF(CF3=20%,"Selesai RPP",IF(CF3<25%,"Proses KAK",IF(CF3=25%,"Selesai KAK",IF(CF3<30%,"Proses Pengadaan",IF(CF3=30%,"Selesai Pengadaan",IF(CF3<45%,"Proses Desain",IF(CF3=45%,"Selesai Desain",IF(CF3<80%,"Proses Pengembangan",IF(CF3=80%,"Selesai Pengembangan",IF(CF3<87.5%,"Proses SIT",IF(CF3=87.5%,"Selesai SIT",IF(CF3<95%,"Proses UAT",IF(CF3=95%,"Selesai UAT",IF(CF3<100%,"Proses Implementasi","Selesai Implementasi")))))))))))))))))))))) -> Not Started | BU3: =IF(CG3=0%,"Not Started",IF(CG3<5%,"Proses RBT-RBB",IF(CG3=5%,"Selesai RBT-RBB",IF(CG3<10%,"Proses RBT-RBL",IF(CG3=10%,"Selesai RBT-RBL",IF(CG3<15%,"Proses RBT-RBTD",IF(CG3=15%,"Selesai RBT-RBTD",IF(CG3<20%,"Proses RPP",IF(CG3=20%,"Selesai RPP",IF(CG3<25%,"Proses KAK",IF(CG3=25%,"Selesai KAK",IF(CG3<30%,"Proses Pengadaan",IF(CG3=30%,"Selesai Pengadaan",IF(CG3<45%,"Proses Desain",IF(CG3=45%,"Selesai Desain",IF(CG3<80%,"Proses Pengembangan",IF(CG3=80%,"Selesai Pengembangan",IF(CG3<87.5%,"Proses SIT",IF(CG3=87.5%,"Selesai SIT",IF(CG3<95%,"Proses UAT",IF(CG3=95%,"Selesai UAT",IF(CG3<100%,"Proses Implementasi","Selesai Implementasi")))))))))))))))))))))) -> Not Started | BV3: =IF(CH3=0%,"Not Started",IF(CH3<5%,"Proses RBT-RBB",IF(CH3=5%,"Selesai RBT-RBB",IF(CH3<10%,"Proses RBT-RBL",IF(CH3=10%,"Selesai RBT-RBL",IF(CH3<15%,"Proses RBT-RBTD",IF(CH3=15%,"Selesai RBT-RBTD",IF(CH3<20%,"Proses RPP",IF(CH3=20%,"Selesai RPP",IF(CH3<25%,"Proses KAK",IF(CH3=25%,"Selesai KAK",IF(CH3<30%,"Proses Pengadaan",IF(CH3=30%,"Selesai Pengadaan",IF(CH3<45%,"Proses Desain",IF(CH3=45%,"Selesai Desain",IF(CH3<80%,"Proses Pengembangan",IF(CH3=80%,"Selesai Pengembangan",IF(CH3<87.5%,"Proses SIT",IF(CH3=87.5%,"Selesai SIT",IF(CH3<95%,"Proses UAT",IF(CH3=95%,"Selesai UAT",IF(CH3<100%,"Proses Implementasi","Selesai Implementasi")))))))))))))))))))))) -> Not Started | BW3: =IF(CI3=0%,"Not Started",IF(CI3<5%,"Proses RBT-RBB",IF(CI3=5%,"Selesai RBT-RBB",IF(CI3<10%,"Proses RBT-RBL",IF(CI3=10%,"Selesai RBT-RBL",IF(CI3<15%,"Proses RBT-RBTD",IF(CI3=15%,"Selesai RBT-RBTD",IF(CI3<20%,"Proses RPP",IF(CI3=20%,"Selesai RPP",IF(CI3<25%,"Proses KAK",IF(CI3=25%,"Selesai KAK",IF(CI3<30%,"Proses Pengadaan",IF(CI3=30%,"Selesai Pengadaan",IF(CI3<45%,"Proses Desain",IF(CI3=45%,"Selesai Desain",IF(CI3<80%,"Proses Pengembangan",IF(CI3=80%,"Selesai Pengembangan",IF(CI3<87.5%,"Proses SIT",IF(CI3=87.5%,"Selesai SIT",IF(CI3<95%,"Proses UAT",IF(CI3=95%,"Selesai UAT",IF(CI3<100%,"Proses Implementasi","Selesai Implementasi")))))))))))))))))))))) -> Not Started | BX3: =IF(CJ3=0%,"Not Started",IF(CJ3<5%,"Proses RBT-RBB",IF(CJ3=5%,"Selesai RBT-RBB",IF(CJ3<10%,"Proses RBT-RBL",IF(CJ3=10%,"Selesai RBT-RBL",IF(CJ3<15%,"Proses RBT-RBTD",IF(CJ3=15%,"Selesai RBT-RBTD",IF(CJ3<20%,"Proses RPP",IF(CJ3=20%,"Selesai RPP",IF(CJ3<25%,"Proses KAK",IF(CJ3=25%,"Selesai KAK",IF(CJ3<30%,"Proses Pengadaan",IF(CJ3=30%,"Selesai Pengadaan",IF(CJ3<45%,"Proses Desain",IF(CJ3=45%,"Selesai Desain",IF(CJ3<80%,"Proses Pengembangan",IF(CJ3=80%,"Selesai Pengembangan",IF(CJ3<87.5%,"Proses SIT",IF(CJ3=87.5%,"Selesai SIT",IF(CJ3<95%,"Proses UAT",IF(CJ3=95%,"Selesai UAT",IF(CJ3<100%,"Proses Implementasi","Selesai Implementasi")))))))))))))))))))))) -> Not Started | ... CB3: =IF(CN3=0%,"Not Started",IF(CN3<5%,"Proses RBT-RBB",IF(CN3=5%,"Selesai RBT-RBB",IF(CN3<10%,"Proses RBT-RBL",IF(CN3=10%,"Selesai RBT-RBL",IF(CN3<15%,"Proses RBT-RBTD",IF(CN3=15%,"Selesai RBT-RBTD",IF(CN3<20%,"Proses RPP",IF(CN3=20%,"Selesai RPP",IF(CN3<25%,"Proses KAK",IF(CN3=25%,"Selesai KAK",IF(CN3<30%,"Proses Pengadaan",IF(CN3=30%,"Selesai Pengadaan",IF(CN3<45%,"Proses Desain",IF(CN3=45%,"Selesai Desain",IF(CN3<80%,"Proses Pengembangan",IF(CN3=80%,"Selesai Pengembangan",IF(CN3<87.5%,"Proses SIT",IF(CN3=87.5%,"Selesai SIT",IF(CN3<95%,"Proses UAT",IF(CN3=95%,"Selesai UAT",IF(CN3<100%,"Proses Implementasi","Selesai Implementasi")))))))))))))))))))))) -> Not Started | CC3: =(($DY3/100%)*15%)+(($DZ3/100%)*5%)+(($EA3/100%)*5%)+(($EB3/100%)*5%)+(($EC3/100%)*15%)+(($ED3/100%)*35%)+(($EE3/100%)*7.5%)+(($EF3/100%)*7.5%)+(($EG3/100%)*5%) -> 0.015 | CO3: =IF(BE3=0%, 100%, (CC3/BE3)) -> 0.25 | CP3: =IF(BF3=0%, 100%, (CD3/BF3)) -> 0 | CQ3: =IF(BG3=0%, 100%, (CE3/BG3)) -> 0 | CR3: =IF(BH3=0%, 100%, (CF3/BH3)) -> 0 | CS3: =IF(BI3=0%, 100%, (CG3/BI3)) -> 0 | CT3: =IF(BJ3=0%, 100%, (CH3/BJ3)) -> 0 | CU3: =IF(BK3=0%, 100%, (CI3/BK3)) -> 0 | CV3: =IF(BL3=0%, 100%, (CJ3/BL3)) -> 0 | ... CY3: =IF(BO3=0%, 100%, (CM3/BO3)) -> 0 | DA3: =IF(BE3=0%,"NS",IF(CC3=100%,"DONE",IF(CO3>100%,"AS",IF(CO3<75%,"BS",IF(CO3<89.9%,"AR","OS"))))) -> BS | DB3: =IF(BF3=0%,"NS",IF(CD3=100%,"DONE",IF(CP3>100%,"AS",IF(CP3<75%,"BS",IF(CP3<89.9%,"AR","OS"))))) -> BS | DC3: =IF(BG3=0%,"NS",IF(CE3=100%,"DONE",IF(CQ3>100%,"AS",IF(CQ3<75%,"BS",IF(CQ3<89.9%,"AR","OS"))))) -> BS | DD3: =IF(BH3=0%,"NS",IF(CF3=100%,"DONE",IF(CR3>100%,"AS",IF(CR3<75%,"BS",IF(CR3<89.9%,"AR","OS"))))) -> BS | DE3: =IF(BI3=0%,"NS",IF(CG3=100%,"DONE",IF(CS3>100%,"AS",IF(CS3<75%,"BS",IF(CS3<89.9%,"AR","OS"))))) -> BS | DF3: =IF(BJ3=0%,"NS",IF(CH3=100%,"DONE",IF(CT3>100%,"AS",IF(CT3<75%,"BS",IF(CT3<89.9%,"AR","OS"))))) -> BS | DG3: =IF(BK3=0%,"NS",IF(CI3=100%,"DONE",IF(CU3>100%,"AS",IF(CU3<75%,"BS",IF(CU3<89.9%,"AR","OS"))))) -> BS | DH3: =IF(BL3=0%,"NS",IF(CJ3=100%,"DONE",IF(CV3>100%,"AS",IF(CV3<75%,"BS",IF(CV3<89.9%,"AR","OS"))))) -> BS | ... DL3: =IF(BP3=0%,"NS",IF(CN3=100%,"DONE",IF(CZ3>100%,"AS",IF(CZ3<75%,"BS",IF(CZ3<89.9%,"AR","OS"))))) -> BS | DM3: =CC3/$BP3 -> 0.05 | DN3: =CD3/$BP3 -> 0 | DO3: =CE3/$BP3 -> 0 | DP3: =CF3/$BP3 -> 0 | DQ3: =CG3/$BP3 -> 0 | DR3: =CH3/$BP3 -> 0 | DS3: =CI3/$BP3 -> 0 | DT3: =CJ3/$BP3 -> 0 | ... DX3: =CN3/$BP3 -> 0 | DY3: 0.1 | EH3: Tindaklanjut 1. RKP (cancel) 2. Cakupan surrounding sebagaimana diskusi tgl 1 Des 2025 pembahasan awal RBT dengan DPID untuk ERP, CBS dan RTGS 3. inisis enhc bifast surrounding tetap dilakukan, dengan minor update 4. Penyusunan RBT inisiasi dari satker bisnis DPSP, dari KMBD minggu lalu belum ada update info dari user 5. Timeline di rivibi untuk DLDS seharusnya sudah dimulai terkait RBT di TW 4 namun saat ini belum ada pembahasan RBT karena menunggu point 1 dan 2 Note DPID: - Dari sisi DPID diperlukan ketersediaan lisensi di DPMA. - Perlu konfirmasi terkait crossborder payment dengan New BI-FAST. (rbt crossborder dipisah) - satker user dari DKSP dan DPPT - PIC KMBD DPID (Pak Eka, Mas Marjon dan Mas Ijul) | EJ3: =AR3 -> 47026 | FN3: Aldo Fernanda | FO3: Among Rogo Wicaksono | FP3: 1. Welly Ramantika 2. Lie Tung Kiam 3. M. Anggasta Paramartha | FQ3: Dian | FR3: Outsource
B4: PT03 | C4: IDPS | E4: P-2 | F4: 3 | G4: BI-RTGS Gen III | H4: BI-RTGS Gen III | I4: Enhancement Aplikasi Legacy BI-RTGS Gen III | J4: 2026 | K4: 2029 | L4: S | M4: K3 | N4: Pemimpin Satker | O4: DKSP, DPSP, DPPT, DIDD, DPPK, DLDS | P4: WG-2 | Q4: SP | R4: SKNBI, BI-SSSS Gen II, CBS, FOMOBO, SWIFT, SOA | S4: =BQ4 -> Not Started | T4: =IF(V4=0%,"Not Started",IF(V4<100%,"On Progress",IF(V4=100%,"DONE"))) -> Not Started | U4: =FN4 -> Aldo Fernanda | V4: =CC4 -> 0 | W4: TW II 2027 | X4: =AR4 -> 47391 | Z4: New | AA4: 46296 | AB4: 46568 | AC4: 46569 | AD4: 46660 | AE4: 46631 | AF4: 46660 | AG4: 46661 | AH4: 46843 | AI4: 46844 | AJ4: 46873 | AK4: 46874 | AL4: 47177 | AM4: 47178 | AN4: 47269 | AO4: 47270 | AP4: 47361 | AQ4: 47362 | AR4: 47391 | AS4: =IF(BE4=0%,"Not Started",IF(BE4<5%,"Proses RBT-RBB",IF(BE4=5%,"Selesai RBT-RBB",IF(BE4<10%,"Proses RBT-RBL",IF(BE4=10%,"Selesai RBT-RBL",IF(BE4<15%,"Proses RBT-RBTD",IF(BE4=15%,"Selesai RBT-RBTD",IF(BE4<20%,"Proses RPP",IF(BE4=20%,"Selesai RPP",IF(BE4<25%,"Proses KAK",IF(BE4=25%,"Selesai KAK",IF(BE4<30%,"Proses Pengadaan",IF(BE4=30%,"Selesai Pengadaan",IF(BE4<45%,"Proses Desain",IF(BE4=45%,"Selesai Desain",IF(BE4<80%,"Proses Pengembangan",IF(BE4=80%,"Selesai Pengembangan",IF(BE4<87.5%,"Proses SIT",IF(BE4=87.5%,"Selesai SIT",IF(BE4<95%,"Proses UAT",IF(BE4=95%,"Selesai UAT",IF(BE4<100%,"Proses Implementasi","Selesai Implementasi")))))))))))))))))))))) -> Not Started | AT4: =IF(BF4=0%,"Not Started",IF(BF4<5%,"Proses RBT-RBB",IF(BF4=5%,"Selesai RBT-RBB",IF(BF4<10%,"Proses RBT-RBL",IF(BF4=10%,"Selesai RBT-RBL",IF(BF4<15%,"Proses RBT-RBTD",IF(BF4=15%,"Selesai RBT-RBTD",IF(BF4<20%,"Proses RPP",IF(BF4=20%,"Selesai RPP",IF(BF4<25%,"Proses KAK",IF(BF4=25%,"Selesai KAK",IF(BF4<30%,"Proses Pengadaan",IF(BF4=30%,"Selesai Pengadaan",IF(BF4<45%,"Proses Desain",IF(BF4=45%,"Selesai Desain",IF(BF4<80%,"Proses Pengembangan",IF(BF4=80%,"Selesai Pengembangan",IF(BF4<87.5%,"Proses SIT",IF(BF4=87.5%,"Selesai SIT",IF(BF4<95%,"Proses UAT",IF(BF4=95%,"Selesai UAT",IF(BF4<100%,"Proses Implementasi","Selesai Implementasi")))))))))))))))))))))) -> Not Started | AU4: =IF(BG4=0%,"Not Started",IF(BG4<5%,"Proses RBT-RBB",IF(BG4=5%,"Selesai RBT-RBB",IF(BG4<10%,"Proses RBT-RBL",IF(BG4=10%,"Selesai RBT-RBL",IF(BG4<15%,"Proses RBT-RBTD",IF(BG4=15%,"Selesai RBT-RBTD",IF(BG4<20%,"Proses RPP",IF(BG4=20%,"Selesai RPP",IF(BG4<25%,"Proses KAK",IF(BG4=25%,"Selesai KAK",IF(BG4<30%,"Proses Pengadaan",IF(BG4=30%,"Selesai Pengadaan",IF(BG4<45%,"Proses Desain",IF(BG4=45%,"Selesai Desain",IF(BG4<80%,"Proses Pengembangan",IF(BG4=80%,"Selesai Pengembangan",IF(BG4<87.5%,"Proses SIT",IF(BG4=87.5%,"Selesai SIT",IF(BG4<95%,"Proses UAT",IF(BG4=95%,"Selesai UAT",IF(BG4<100%,"Proses Implementasi","Selesai Implementasi")))))))))))))))))))))) -> Not Started | AV4: =IF(BH4=0%,"Not Started",IF(BH4<5%,"Proses RBT-RBB",IF(BH4=5%,"Selesai RBT-RBB",IF(BH4<10%,"Proses RBT-RBL",IF(BH4=10%,"Selesai RBT-RBL",IF(BH4<15%,"Proses RBT-RBTD",IF(BH4=15%,"Selesai RBT-RBTD",IF(BH4<20%,"Proses RPP",IF(BH4=20%,"Selesai RPP",IF(BH4<25%,"Proses KAK",IF(BH4=25%,"Selesai KAK",IF(BH4<30%,"Proses Pengadaan",IF(BH4=30%,"Selesai Pengadaan",IF(BH4<45%,"Proses Desain",IF(BH4=45%,"Selesai Desain",IF(BH4<80%,"Proses Pengembangan",IF(BH4=80%,"Selesai Pengembangan",IF(BH4<87.5%,"Proses SIT",IF(BH4=87.5%,"Selesai SIT",IF(BH4<95%,"Proses UAT",IF(BH4=95%,"Selesai UAT",IF(BH4<100%,"Proses Implementasi","Selesai Implementasi")))))))))))))))))))))) -> Not Started | AW4: =IF(BI4=0%,"Not Started",IF(BI4<5%,"Proses RBT-RBB",IF(BI4=5%,"Selesai RBT-RBB",IF(BI4<10%,"Proses RBT-RBL",IF(BI4=10%,"Selesai RBT-RBL",IF(BI4<15%,"Proses RBT-RBTD",IF(BI4=15%,"Selesai RBT-RBTD",IF(BI4<20%,"Proses RPP",IF(BI4=20%,"Selesai RPP",IF(BI4<25%,"Proses KAK",IF(BI4=25%,"Selesai KAK",IF(BI4<30%,"Proses Pengadaan",IF(BI4=30%,"Selesai Pengadaan",IF(BI4<45%,"Proses Desain",IF(BI4=45%,"Selesai Desain",IF(BI4<80%,"Proses Pengembangan",IF(BI4=80%,"Selesai Pengembangan",IF(BI4<87.5%,"Proses SIT",IF(BI4=87.5%,"Selesai SIT",IF(BI4<95%,"Proses UAT",IF(BI4=95%,"Selesai UAT",IF(BI4<100%,"Proses Implementasi","Selesai Implementasi")))))))))))))))))))))) -> Not Started | AX4: =IF(BJ4=0%,"Not Started",IF(BJ4<5%,"Proses RBT-RBB",IF(BJ4=5%,"Selesai RBT-RBB",IF(BJ4<10%,"Proses RBT-RBL",IF(BJ4=10%,"Selesai RBT-RBL",IF(BJ4<15%,"Proses RBT-RBTD",IF(BJ4=15%,"Selesai RBT-RBTD",IF(BJ4<20%,"Proses RPP",IF(BJ4=20%,"Selesai RPP",IF(BJ4<25%,"Proses KAK",IF(BJ4=25%,"Selesai KAK",IF(BJ4<30%,"Proses Pengadaan",IF(BJ4=30%,"Selesai Pengadaan",IF(BJ4<45%,"Proses Desain",IF(BJ4=45%,"Selesai Desain",IF(BJ4<80%,"Proses Pengembangan",IF(BJ4=80%,"Selesai Pengembangan",IF(BJ4<87.5%,"Proses SIT",IF(BJ4=87.5%,"Selesai SIT",IF(BJ4<95%,"Proses UAT",IF(BJ4=95%,"Selesai UAT",IF(BJ4<100%,"Proses Implementasi","Selesai Implementasi")))))))))))))))))))))) -> Not Started | AY4: =IF(BK4=0%,"Not Started",IF(BK4<5%,"Proses RBT-RBB",IF(BK4=5%,"Selesai RBT-RBB",IF(BK4<10%,"Proses RBT-RBL",IF(BK4=10%,"Selesai RBT-RBL",IF(BK4<15%,"Proses RBT-RBTD",IF(BK4=15%,"Selesai RBT-RBTD",IF(BK4<20%,"Proses RPP",IF(BK4=20%,"Selesai RPP",IF(BK4<25%,"Proses KAK",IF(BK4=25%,"Selesai KAK",IF(BK4<30%,"Proses Pengadaan",IF(BK4=30%,"Selesai Pengadaan",IF(BK4<45%,"Proses Desain",IF(BK4=45%,"Selesai Desain",IF(BK4<80%,"Proses Pengembangan",IF(BK4=80%,"Selesai Pengembangan",IF(BK4<87.5%,"Proses SIT",IF(BK4=87.5%,"Selesai SIT",IF(BK4<95%,"Proses UAT",IF(BK4=95%,"Selesai UAT",IF(BK4<100%,"Proses Implementasi","Selesai Implementasi")))))))))))))))))))))) -> Not Started | AZ4: =IF(BL4=0%,"Not Started",IF(BL4<5%,"Proses RBT-RBB",IF(BL4=5%,"Selesai RBT-RBB",IF(BL4<10%,"Proses RBT-RBL",IF(BL4=10%,"Selesai RBT-RBL",IF(BL4<15%,"Proses RBT-RBTD",IF(BL4=15%,"Selesai RBT-RBTD",IF(BL4<20%,"Proses RPP",IF(BL4=20%,"Selesai RPP",IF(BL4<25%,"Proses KAK",IF(BL4=25%,"Selesai KAK",IF(BL4<30%,"Proses Pengadaan",IF(BL4=30%,"Selesai Pengadaan",IF(BL4<45%,"Proses Desain",IF(BL4=45%,"Selesai Desain",IF(BL4<80%,"Proses Pengembangan",IF(BL4=80%,"Selesai Pengembangan",IF(BL4<87.5%,"Proses SIT",IF(BL4=87.5%,"Selesai SIT",IF(BL4<95%,"Proses UAT",IF(BL4=95%,"Selesai UAT",IF(BL4<100%,"Proses Implementasi","Selesai Implementasi")))))))))))))))))))))) -> Not Started | ... BD4: =IF(BP4=0%,"Not Started",IF(BP4<5%,"Proses RBT-RBB",IF(BP4=5%,"Selesai RBT-RBB",IF(BP4<10%,"Proses RBT-RBL",IF(BP4=10%,"Selesai RBT-RBL",IF(BP4<15%,"Proses RBT-RBTD",IF(BP4=15%,"Selesai RBT-RBTD",IF(BP4<20%,"Proses RPP",IF(BP4=20%,"Selesai RPP",IF(BP4<25%,"Proses KAK",IF(BP4=25%,"Selesai KAK",IF(BP4<30%,"Proses Pengadaan",IF(BP4=30%,"Selesai Pengadaan",IF(BP4<45%,"Proses Desain",IF(BP4=45%,"Selesai Desain",IF(BP4<80%,"Proses Pengembangan",IF(BP4=80%,"Selesai Pengembangan",IF(BP4<87.5%,"Proses SIT",IF(BP4=87.5%,"Selesai SIT",IF(BP4<95%,"Proses UAT",IF(BP4=95%,"Selesai UAT",IF(BP4<100%,"Proses Implementasi","Selesai Implementasi")))))))))))))))))))))) -> Proses RBT-RBB | BE4: 0 | BF4: 0 | BG4: 0 | BH4: 0 | BI4: 0 | BJ4: 0 | BK4: 0 | BL4: 0 | BM4: 0 | BN4: 0.01 | BO4: 0.02 | BP4: 0.03 | BQ4: =IF(CC4=0%,"Not Started",IF(CC4<5%,"Proses RBT-RBB",IF(CC4=5%,"Selesai RBT-RBB",IF(CC4<10%,"Proses RBT-RBL",IF(CC4=10%,"Selesai RBT-RBL",IF(CC4<15%,"Proses RBT-RBTD",IF(CC4=15%,"Selesai RBT-RBTD",IF(CC4<20%,"Proses RPP",IF(CC4=20%,"Selesai RPP",IF(CC4<25%,"Proses KAK",IF(CC4=25%,"Selesai KAK",IF(CC4<30%,"Proses Pengadaan",IF(CC4=30%,"Selesai Pengadaan",IF(CC4<45%,"Proses Desain",IF(CC4=45%,"Selesai Desain",IF(CC4<80%,"Proses Pengembangan",IF(CC4=80%,"Selesai Pengembangan",IF(CC4<87.5%,"Proses SIT",IF(CC4=87.5%,"Selesai SIT",IF(CC4<95%,"Proses UAT",IF(CC4=95%,"Selesai UAT",IF(CC4<100%,"Proses Implementasi","Selesai Implementasi")))))))))))))))))))))) -> Not Started | BR4: =IF(CD4=0%,"Not Started",IF(CD4<5%,"Proses RBT-RBB",IF(CD4=5%,"Selesai RBT-RBB",IF(CD4<10%,"Proses RBT-RBL",IF(CD4=10%,"Selesai RBT-RBL",IF(CD4<15%,"Proses RBT-RBTD",IF(CD4=15%,"Selesai RBT-RBTD",IF(CD4<20%,"Proses RPP",IF(CD4=20%,"Selesai RPP",IF(CD4<25%,"Proses KAK",IF(CD4=25%,"Selesai KAK",IF(CD4<30%,"Proses Pengadaan",IF(CD4=30%,"Selesai Pengadaan",IF(CD4<45%,"Proses Desain",IF(CD4=45%,"Selesai Desain",IF(CD4<80%,"Proses Pengembangan",IF(CD4=80%,"Selesai Pengembangan",IF(CD4<87.5%,"Proses SIT",IF(CD4=87.5%,"Selesai SIT",IF(CD4<95%,"Proses UAT",IF(CD4=95%,"Selesai UAT",IF(CD4<100%,"Proses Implementasi","Selesai Implementasi")))))))))))))))))))))) -> Not Started | BS4: =IF(CE4=0%,"Not Started",IF(CE4<5%,"Proses RBT-RBB",IF(CE4=5%,"Selesai RBT-RBB",IF(CE4<10%,"Proses RBT-RBL",IF(CE4=10%,"Selesai RBT-RBL",IF(CE4<15%,"Proses RBT-RBTD",IF(CE4=15%,"Selesai RBT-RBTD",IF(CE4<20%,"Proses RPP",IF(CE4=20%,"Selesai RPP",IF(CE4<25%,"Proses KAK",IF(CE4=25%,"Selesai KAK",IF(CE4<30%,"Proses Pengadaan",IF(CE4=30%,"Selesai Pengadaan",IF(CE4<45%,"Proses Desain",IF(CE4=45%,"Selesai Desain",IF(CE4<80%,"Proses Pengembangan",IF(CE4=80%,"Selesai Pengembangan",IF(CE4<87.5%,"Proses SIT",IF(CE4=87.5%,"Selesai SIT",IF(CE4<95%,"Proses UAT",IF(CE4=95%,"Selesai UAT",IF(CE4<100%,"Proses Implementasi","Selesai Implementasi")))))))))))))))))))))) -> Not Started | BT4: =IF(CF4=0%,"Not Started",IF(CF4<5%,"Proses RBT-RBB",IF(CF4=5%,"Selesai RBT-RBB",IF(CF4<10%,"Proses RBT-RBL",IF(CF4=10%,"Selesai RBT-RBL",IF(CF4<15%,"Proses RBT-RBTD",IF(CF4=15%,"Selesai RBT-RBTD",IF(CF4<20%,"Proses RPP",IF(CF4=20%,"Selesai RPP",IF(CF4<25%,"Proses KAK",IF(CF4=25%,"Selesai KAK",IF(CF4<30%,"Proses Pengadaan",IF(CF4=30%,"Selesai Pengadaan",IF(CF4<45%,"Proses Desain",IF(CF4=45%,"Selesai Desain",IF(CF4<80%,"Proses Pengembangan",IF(CF4=80%,"Selesai Pengembangan",IF(CF4<87.5%,"Proses SIT",IF(CF4=87.5%,"Selesai SIT",IF(CF4<95%,"Proses UAT",IF(CF4=95%,"Selesai UAT",IF(CF4<100%,"Proses Implementasi","Selesai Implementasi")))))))))))))))))))))) -> Not Started | BU4: =IF(CG4=0%,"Not Started",IF(CG4<5%,"Proses RBT-RBB",IF(CG4=5%,"Selesai RBT-RBB",IF(CG4<10%,"Proses RBT-RBL",IF(CG4=10%,"Selesai RBT-RBL",IF(CG4<15%,"Proses RBT-RBTD",IF(CG4=15%,"Selesai RBT-RBTD",IF(CG4<20%,"Proses RPP",IF(CG4=20%,"Selesai RPP",IF(CG4<25%,"Proses KAK",IF(CG4=25%,"Selesai KAK",IF(CG4<30%,"Proses Pengadaan",IF(CG4=30%,"Selesai Pengadaan",IF(CG4<45%,"Proses Desain",IF(CG4=45%,"Selesai Desain",IF(CG4<80%,"Proses Pengembangan",IF(CG4=80%,"Selesai Pengembangan",IF(CG4<87.5%,"Proses SIT",IF(CG4=87.5%,"Selesai SIT",IF(CG4<95%,"Proses UAT",IF(CG4=95%,"Selesai UAT",IF(CG4<100%,"Proses Implementasi","Selesai Implementasi")))))))))))))))))))))) -> Not Started | BV4: =IF(CH4=0%,"Not Started",IF(CH4<5%,"Proses RBT-RBB",IF(CH4=5%,"Selesai RBT-RBB",IF(CH4<10%,"Proses RBT-RBL",IF(CH4=10%,"Selesai RBT-RBL",IF(CH4<15%,"Proses RBT-RBTD",IF(CH4=15%,"Selesai RBT-RBTD",IF(CH4<20%,"Proses RPP",IF(CH4=20%,"Selesai RPP",IF(CH4<25%,"Proses KAK",IF(CH4=25%,"Selesai KAK",IF(CH4<30%,"Proses Pengadaan",IF(CH4=30%,"Selesai Pengadaan",IF(CH4<45%,"Proses Desain",IF(CH4=45%,"Selesai Desain",IF(CH4<80%,"Proses Pengembangan",IF(CH4=80%,"Selesai Pengembangan",IF(CH4<87.5%,"Proses SIT",IF(CH4=87.5%,"Selesai SIT",IF(CH4<95%,"Proses UAT",IF(CH4=95%,"Selesai UAT",IF(CH4<100%,"Proses Implementasi","Selesai Implementasi")))))))))))))))))))))) -> Not Started | BW4: =IF(CI4=0%,"Not Started",IF(CI4<5%,"Proses RBT-RBB",IF(CI4=5%,"Selesai RBT-RBB",IF(CI4<10%,"Proses RBT-RBL",IF(CI4=10%,"Selesai RBT-RBL",IF(CI4<15%,"Proses RBT-RBTD",IF(CI4=15%,"Selesai RBT-RBTD",IF(CI4<20%,"Proses RPP",IF(CI4=20%,"Selesai RPP",IF(CI4<25%,"Proses KAK",IF(CI4=25%,"Selesai KAK",IF(CI4<30%,"Proses Pengadaan",IF(CI4=30%,"Selesai Pengadaan",IF(CI4<45%,"Proses Desain",IF(CI4=45%,"Selesai Desain",IF(CI4<80%,"Proses Pengembangan",IF(CI4=80%,"Selesai Pengembangan",IF(CI4<87.5%,"Proses SIT",IF(CI4=87.5%,"Selesai SIT",IF(CI4<95%,"Proses UAT",IF(CI4=95%,"Selesai UAT",IF(CI4<100%,"Proses Implementasi","Selesai Implementasi")))))))))))))))))))))) -> Not Started | BX4: =IF(CJ4=0%,"Not Started",IF(CJ4<5%,"Proses RBT-RBB",IF(CJ4=5%,"Selesai RBT-RBB",IF(CJ4<10%,"Proses RBT-RBL",IF(CJ4=10%,"Selesai RBT-RBL",IF(CJ4<15%,"Proses RBT-RBTD",IF(CJ4=15%,"Selesai RBT-RBTD",IF(CJ4<20%,"Proses RPP",IF(CJ4=20%,"Selesai RPP",IF(CJ4<25%,"Proses KAK",IF(CJ4=25%,"Selesai KAK",IF(CJ4<30%,"Proses Pengadaan",IF(CJ4=30%,"Selesai Pengadaan",IF(CJ4<45%,"Proses Desain",IF(CJ4=45%,"Selesai Desain",IF(CJ4<80%,"Proses Pengembangan",IF(CJ4=80%,"Selesai Pengembangan",IF(CJ4<87.5%,"Proses SIT",IF(CJ4=87.5%,"Selesai SIT",IF(CJ4<95%,"Proses UAT",IF(CJ4=95%,"Selesai UAT",IF(CJ4<100%,"Proses Implementasi","Selesai Implementasi")))))))))))))))))))))) -> Not Started | ... CB4: =IF(CN4=0%,"Not Started",IF(CN4<5%,"Proses RBT-RBB",IF(CN4=5%,"Selesai RBT-RBB",IF(CN4<10%,"Proses RBT-RBL",IF(CN4=10%,"Selesai RBT-RBL",IF(CN4<15%,"Proses RBT-RBTD",IF(CN4=15%,"Selesai RBT-RBTD",IF(CN4<20%,"Proses RPP",IF(CN4=20%,"Selesai RPP",IF(CN4<25%,"Proses KAK",IF(CN4=25%,"Selesai KAK",IF(CN4<30%,"Proses Pengadaan",IF(CN4=30%,"Selesai Pengadaan",IF(CN4<45%,"Proses Desain",IF(CN4=45%,"Selesai Desain",IF(CN4<80%,"Proses Pengembangan",IF(CN4=80%,"Selesai Pengembangan",IF(CN4<87.5%,"Proses SIT",IF(CN4=87.5%,"Selesai SIT",IF(CN4<95%,"Proses UAT",IF(CN4=95%,"Selesai UAT",IF(CN4<100%,"Proses Implementasi","Selesai Implementasi")))))))))))))))))))))) -> Not Started | CC4: =(($DY4/100%)*15%)+(($DZ4/100%)*5%)+(($EA4/100%)*5%)+(($EB4/100%)*5%)+(($EC4/100%)*15%)+(($ED4/100%)*35%)+(($EE4/100%)*7.5%)+(($EF4/100%)*7.5%)+(($EG4/100%)*5%) -> 0 | CO4: =IF(BE4=0%, 100%, (CC4/BE4)) -> 1 | CP4: =IF(BF4=0%, 100%, (CD4/BF4)) -> 1 | CQ4: =IF(BG4=0%, 100%, (CE4/BG4)) -> 1 | CR4: =IF(BH4=0%, 100%, (CF4/BH4)) -> 1 | CS4: =IF(BI4=0%, 100%, (CG4/BI4)) -> 1 | CT4: =IF(BJ4=0%, 100%, (CH4/BJ4)) -> 1 | CU4: =IF(BK4=0%, 100%, (CI4/BK4)) -> 1 | CV4: =IF(BL4=0%, 100%, (CJ4/BL4)) -> 1 | ... CY4: =IF(BO4=0%, 100%, (CM4/BO4)) -> 0 | DA4: =IF(BE4=0%,"NS",IF(CC4=100%,"DONE",IF(CO4>100%,"AS",IF(CO4<75%,"BS",IF(CO4<89.9%,"AR","OS"))))) -> NS | DB4: =IF(BF4=0%,"NS",IF(CD4=100%,"DONE",IF(CP4>100%,"AS",IF(CP4<75%,"BS",IF(CP4<89.9%,"AR","OS"))))) -> NS | DC4: =IF(BG4=0%,"NS",IF(CE4=100%,"DONE",IF(CQ4>100%,"AS",IF(CQ4<75%,"BS",IF(CQ4<89.9%,"AR","OS"))))) -> NS | DD4: =IF(BH4=0%,"NS",IF(CF4=100%,"DONE",IF(CR4>100%,"AS",IF(CR4<75%,"BS",IF(CR4<89.9%,"AR","OS"))))) -> NS | DE4: =IF(BI4=0%,"NS",IF(CG4=100%,"DONE",IF(CS4>100%,"AS",IF(CS4<75%,"BS",IF(CS4<89.9%,"AR","OS"))))) -> NS | DF4: =IF(BJ4=0%,"NS",IF(CH4=100%,"DONE",IF(CT4>100%,"AS",IF(CT4<75%,"BS",IF(CT4<89.9%,"AR","OS"))))) -> NS | DG4: =IF(BK4=0%,"NS",IF(CI4=100%,"DONE",IF(CU4>100%,"AS",IF(CU4<75%,"BS",IF(CU4<89.9%,"AR","OS"))))) -> NS | DH4: =IF(BL4=0%,"NS",IF(CJ4=100%,"DONE",IF(CV4>100%,"AS",IF(CV4<75%,"BS",IF(CV4<89.9%,"AR","OS"))))) -> NS | ... DL4: =IF(BP4=0%,"NS",IF(CN4=100%,"DONE",IF(CZ4>100%,"AS",IF(CZ4<75%,"BS",IF(CZ4<89.9%,"AR","OS"))))) -> BS | DM4: =CC4/$BP4 -> 0 | DN4: =CD4/$BP4 -> 0 | DO4: =CE4/$BP4 -> 0 | DP4: =CF4/$BP4 -> 0 | DQ4: =CG4/$BP4 -> 0 | DR4: =CH4/$BP4 -> 0 | DS4: =CI4/$BP4 -> 0 | DT4: =CJ4/$BP4 -> 0 | ... DX4: =CN4/$BP4 -> 0 | EH4: tindaklanjut: 1. perlu konfirmasi ke User DPSP dan DPPT terkait jadwal pembahasan RBT (to do) Note: pembahasan konsinyering Bandung 1-2 Des 2025 1. pembahasan RBT baru akan dilanjutkan kembali dari sisi user karena sebelum nya sempat pending dikarenakan prioritas proyek lainnya 2. terdapat konfirmasi dari sisi User ke DLDS untuk pengembangan RMB pada RTGS Gen 2 namun hambatan nya pada kesediaan aplikasi surrounding, waktu persiapan dan masa pakai sampai Gen 3 mulai beroperasi 3. konfirmasi dampak RTGS Gen 3 ke surrounding seperti TMSX, CBS dan timeline surrounding dengan RTGS Gen 3 | EJ4: =AR4 -> 47391 | FM4: Faradilla Anggun S. | FN4: Aldo Fernanda | FO4: Among Rogo Wicaksono | FP4: 1. Welly Ramantika 2. Lie Tung Kiam 3. Elsameinar | FQ4: Dian | FR4: Outsource
